<?xml version='1.0'?>
<sdf version='1.4'>
  <model name="my_robot">
	<static>false</static>
          <link name='chassis'>
            <pose>-0.01724 0.20090 0.77937 0 0 0</pose>
		

            <!--collision name='collision'>
              <geometry>
                <box>
                  <size>1.14 4.3 1.12</size>
                </box>
              </geometry>
            </collision-->

            <!--visual name='visual'>
              <geometry>
                <box>
                  <size>1.16 4.3 1.12</size><z=1.32/1.12,x=1.8-2*0.315>
                </box>
              </geometry>
            </visual-->
	    <visual name='visual'>	
	      <geometry>
		<mesh>
		  <uri>model://my_robot/meshes/my_car_chassis.dae</uri>
		</mesh>
	      </geometry>
	    </visual>


          <!--collision name='caster_collision'>
            <pose>-0.15 0 -0.05 0 0 0</pose>
            <geometry>
                <sphere>
                <radius>.05</radius>
              </sphere>
            </geometry>

            <surface>
              <friction>
                <ode>
                  <mu>0</mu>
                  <mu2>0</mu2>
                  <slip1>1.0</slip1>
                  <slip2>1.0</slip2>
                </ode>
              </friction>
            </surface>
          </collision-->

          <!--visual name='caster_visual'>
            <pose>-0.15 0 -0.05 0 0 0</pose>
            <geometry>
              <sphere>
                <radius>.05</radius>
              </sphere>
            </geometry>
          </visual-->
          </link>


      <link name="front_left_wheel">
        <pose>-0.67 1.5 0.35 0 1.5707 0</pose>
        
        <collision name="collision">
          <geometry>
            <cylinder>
              <radius>.35</radius>
              <length>.315</length>
            </cylinder>
          </geometry>
        </collision>

        <!--visual name="visual">
          <geometry>
            <cylinder>
              <radius>.35</radius>
              <length>.315</length>
            </cylinder>
          </geometry>
        </visual-->

<visual name='visual'>
	<!--pose>0 0 0 0 -1.5707 0</pose-->	
	      <geometry>
		<mesh>
		  <uri>model://my_robot/meshes/my_car_wheel.dae</uri>
		</mesh>
	      </geometry>
	    </visual>




      </link>

      <link name="front_right_wheel">
        <pose>0.64 1.5 0.35 0 1.5707 0</pose>

        <collision name="collision">
          <geometry>
            <cylinder>
              <radius>.35</radius>
              <length>.315</length>
            </cylinder>
          </geometry>
        </collision>

        <!--visual name="visual">
          <geometry>
            <cylinder>
              <radius>.35</radius>
              <length>.315</length>
            </cylinder>
          </geometry>
        </visual-->

<visual name='visual'>
	<!--pose>0 0 0 0 -1.5707 0</pose-->	
	      <geometry>
		<mesh>
		  <uri>model://my_robot/meshes/my_car_wheel.dae</uri>
		</mesh>
	      </geometry>
	    </visual>



      </link>

      <link name="rear_left_wheel">
        <pose>-0.67 -1.15 0.35 0 1.5707 0</pose>

        <collision name="collision">
          <geometry>
            <cylinder>
              <radius>.35</radius>
              <length>.315</length>
            </cylinder>
          </geometry>
        </collision>

        <!--visual name="visual">
          <geometry>
            <cylinder>
              <radius>.35</radius>
              <length>.315</length>
            </cylinder>
          </geometry>
        </visual-->

<visual name='visual'>
	<!--pose>0 0 0 0 -1.5707 0</pose-->	
	      <geometry>
		<mesh>
		  <uri>model://my_robot/meshes/my_car_wheel.dae</uri>
		</mesh>
	      </geometry>
	    </visual>



      </link>

      <link name="rear_right_wheel">
        <pose>0.64 -1.15 0.35 0 1.5707 0</pose>

        <collision name="collision">
          <geometry>
            <cylinder>
              <radius>.35</radius>
              <length>.315</length>
            </cylinder>
          </geometry>
        </collision>

        <!--visual name="visual">
          <geometry>
            <cylinder>
              <radius>.35</radius>
              <length>.315</length>
            </cylinder>
          </geometry>
        </visual-->

<visual name='visual'>
	<!--pose>0 0 0 0 -1.5707 0</pose-->	
	      <geometry>
		<mesh>
		  <uri>model://my_robot/meshes/my_car_wheel.dae</uri>
		</mesh>
	      </geometry>
	    </visual>

      </link>

      <joint type="revolute" name="front_left_wheel_hinge">
        <pose>0 0 -0.155 0 0 0</pose>
        <child>front_left_wheel</child>
        <parent>chassis</parent>
        <axis>
          <xyz>1 0 0</xyz>
        </axis>
      </joint>

      <joint type="revolute" name="rear_left_wheel_hinge">
        <pose>0 0 -0.155 0 0 0</pose>
        <child>rear_left_wheel</child>
        <parent>chassis</parent>
        <axis>
          <xyz>1 0 0</xyz>
        </axis>
      </joint>

      <joint type="revolute" name="front_right_wheel_hinge">
        <pose>0 0 0.155 0 0 0</pose>
        <child>front_right_wheel</child>
        <parent>chassis</parent>
        <axis>
          <xyz>1 0 0</xyz>
        </axis>
      </joint>

      <joint type="revolute" name="rear_right_wheel_hinge">
        <pose>0 0 0.155 0 0 0</pose>
        <child>rear_right_wheel</child>
        <parent>chassis</parent>
        <axis>
          <xyz>1 0 0</xyz>
        </axis>
      </joint>

	<plugin name="model_push" filename="libmodel_push.so">

  </model>
</sdf>




